Workbook

Sheet Lisez-moi
A1: Flashcards de mathématiques BCPST – tableur source de l'application
A2: Ce fichier alimente l'application : après modification, le déposer sur GitHub dans source/ (même nom). Ne jamais changer un ID : il porte la progression des élèves.
A3: Source des fiches : captures de l'ouvrage Dunod (pages 1 à 104, partie mathématiques). Référence : programme officiel BCPST 2021 (PDF, Annexe 3).
A5: Code couleur (couleur du texte de chaque ligne de l'onglet Fiches)
A6: Noir : contenu explicitement au programme (citation dans la colonne Justification). Détails annexes éventuels signalés en Remarque.
A7: Orange : programme muet ou ambigu, ou contenu au programme mais explicitement fourni dans les énoncés (inutile à mémoriser).
A8: Rouge : explicitement exclu par le programme (« hors programme », « pas un attendu », « non exigible », « aucune formule n'est à connaître »).
A10: Ce que tu as à faire
A11: 1. Onglet Fiches : lire la colonne Justification (citation du programme) et vérifier que le statut te convient.
A12: 2. Colonne « Ta décision » (fond jaune) : choisir dans la liste. Laisser vide = d'accord avec ma proposition.
A13: 3. Colonne « Ton commentaire » : correction de contenu, reformulation, etc.
A14: 4. Onglet Formulaire : pages 98 à 104 de l'ouvrage, une égalité par carte (recto = membre de gauche, verso = membre de droite). Mêmes colonnes de décision. Les fiches de l'onglet Fiches citées en « Fiche d'origine » ne sont pas reprises dans le jeu principal.
... A23: • Les fiches sont triées dans l'ordre du programme ; la colonne Page renvoie à l'ouvrage.

Sheet Fiches
A1: ID | B1: Statut | C1: Année | D1: Partie du programme | E1: Type | F1: Intitulé (recto) | G1: Contenu (verso) | H1: Justification (programme 2021) | I1: Page ouvrage | J1: Remarque | K1: Ta décision | L1: Ton commentaire
A2: M001 | B2: Noir – conforme | C2: BCPST1 | D2: BCPST1 · Outils 1 – Logique, ensembles | E2: Définition | F2: Inclusion d'ensembles – Définition | G2: $A\subset B$ si $x\in A\Rightarrow x\in B$. | H2: « Sous-ensemble (ou partie), inclusion. » | I2: 71
A3: M002 | B3: Noir – conforme | C3: BCPST1 | D3: BCPST1 · Outils 1 – Logique, ensembles | E3: Définition | F3: Opérations sur les ensembles – Définition | G3: Union $A\cup B$, intersection $A\cap B$, différence $B\setminus A$ ; complémentaire $\bar A=\Omega\setminus A$. | H3: « Réunion. Intersection. Complémentaire. » | I3: 72
A4: M003 | B4: Noir – conforme | C4: BCPST1 | D4: BCPST1 · Outils 1 – Logique, ensembles | E4: Propriété | F4: Opérations sur les ensembles – Règles de calcul | G4: Commutativité ; distributivité de $\cup$ sur $\cap$ et réciproquement ; lois de De Morgan : $\overline{A\cup B}=\bar A\cap\bar B$, $\overline{A\cap B}=\bar A\cup\bar B$ (et pour une famille). | H4: « Complémentaire d'une union et d'une intersection, distributivité de ∪ sur ∩ et de ∩ sur ∪. On se limite aux unions et intersections finies. » (BCPST2 : ∪Aₙ et ∩Aₙ dénombrables) | I4: 72
A5: M004 | B5: Noir – conforme | C5: BCPST1 | D5: BCPST1 · Outils 1 – Logique, ensembles | E5: Définition | F5: Produits cartésiens d'ensembles – Définition | G5: $A\times B$ : ensemble des couples $(x,y)$, $x\in A$, $y\in B$ ; $A_1\times\dots\times A_n$ : ensemble des $n$-uplets ; $E^n=E\times\dots\times E$. | H5: « Couple, p-uplet. Produit cartésien. » | I5: 73
A6: M005 | B6: Orange – incertain | C6: BCPST1 | D6: BCPST1 · Outils 2 – Nombres réels | E6: Propriété | F6: ℚ est dense | G6: Pour tous réels $x<y$, il existe un rationnel $z$ tel que $x<z<y$. | H6: « Les ensembles N, Z, Q et R sont supposés connus. » La densité de Q n'est pas mentionnée. | I6: 3
A7: M006 | B7: Noir – conforme | C7: BCPST1 | D7: BCPST1 · Outils 2 – Nombres réels | E7: Propriété | F7: Présentation (ordre et borne supérieure) | G7: $a\le b\Rightarrow a+c\le b+c$ ; $a\le b$ et $c\ge0\Rightarrow ac\le bc$. Toute partie non vide majorée de $\mathbb R$ admet une borne supérieure. | H7: « Manipulation des inégalités … On admet l'existence de la borne supérieure d'une partie majorée non vide. » | I7: 18
A8: M007 | B8: Noir – conforme | C8: BCPST1 | D8: BCPST1 · Outils 2 – Nombres réels | E8: Définition | F8: Partie entière – Définition | G8: $E(x)=\lfloor x\rfloor$ est l'unique entier tel que $E(x)\le x<E(x)+1$. | H8: « Partie entière … notation ⌊·⌋ ». | I8: 18
A9: M008 | B9: Noir – conforme | C9: BCPST1 | D9: BCPST1 · Outils 3 – Trigonométrie | E9: Propriété | F9: Factorisation de a cos θ + b sin θ | G9: $a\cos\theta+b\sin\theta=r\cos(\theta+\varphi)$ avec $r=\sqrt{a^2+b^2}$, $\cos\varphi=\frac ar$, $\sin\varphi=-\frac br$ (forme du programme). | H9: « Transformation de a cos(θ) + b sin(θ) en r cos(θ + ϕ). La méthode … n'est pas imposée. » | I9: 21 | J9: ERREUR DANS L'OUVRAGE : il écrit $r\cos(\theta+\varphi)$ avec $\sin\varphi=b/r$ ; avec cette convention il faut $\sin\varphi=-b/r$ (ou bien $r\cos(\theta-\varphi)$). Corrigé ici dans la forme du programme
A10: M009 | B10: Orange – incertain | C10: BCPST1 | D10: BCPST1 · Outils 3 – Trigonométrie | E10: Propriété | F10: Fonctions Arcsin et Arccos et leurs dérivées | G10: $\arcsin:[-1,1]\to[-\frac\pi2,\frac\pi2]$, $\arcsin'(x)=\frac1{\sqrt{1-x^2}}$ ; $\arccos:[-1,1]\to[0,\pi]$, $\arccos'(x)=-\frac1{\sqrt{1-x^2}}$ (sur $]-1,1[$). | H10: Notations arccos, arcsin introduites (solutions d'équations), mais « La construction des fonctions arccosinus et arcsinus n'est pas un attendu du programme » ; leurs dérivées ne sont pas citées. | I10: 31 | J10: Fiche détachée d'un cadre de l'ouvrage (contenu partiellement hors programme)
A11: M010 | B11: Noir – conforme | C11: BCPST1 | D11: BCPST1 · Outils 3 – Trigonométrie | E11: Formulaire | F11: Valeurs remarquables de sin, cos, tan | G11: En $0,\frac\pi6,\frac\pi4,\frac\pi3,\frac\pi2,\pi$ : $\sin$ : $0,\frac12,\frac{\sqrt2}2,\frac{\sqrt3}2,1,0$ ; $\cos$ : $1,\frac{\sqrt3}2,\frac{\sqrt2}2,\frac12,0,-1$ ; $\tan$ : $0,\frac{\sqrt3}3,1,\sqrt3,\text{non défini},0$. | H11: « Définition de cos(θ), sin(θ) et tan(θ). Périodicité et symétries. » | I11: 102 | J11: Tableau (pas de cadre titré) : intitulé créé par moi
A12: M011 | B12: Noir – conforme | C12: BCPST1 | D12: BCPST1 · Outils 3 – Trigonométrie | E12: Formulaire | F12: Relations entre les rapports trigonométriques d'un même arc | G12: $\cos^2a+\sin^2a=1$ ; $\tan a=\frac{\sin a}{\cos a}$ ; $1+\tan^2a=\frac1{\cos^2a}$. | H12: « cos²(θ) + sin²(θ) = 1 » ; A2 : « tan' = 1 + tan² = 1/cos² ». (formules en cot : fiche séparée, hors programme) | I12: 102 | J12: Formules avec la cotangente placées dans une fiche séparée
A13: M012 | B13: Rouge – hors programme | C13: BCPST1 | D13: BCPST1 · Outils 3 – Trigonométrie | E13: Formulaire | F13: Relations avec la cotangente | G13: $\cot a=\frac{\cos a}{\sin a}$ ; $1+\cot^2a=\frac1{\sin^2a}$ ; $\cos^2a=\frac1{1+\tan^2a}$ ; $\sin^2a=\frac1{1+\cot^2a}$. | H13: « Les autres formules de trigonométrie ne sont pas des attendus du programme. » | I13: 102 | J13: Fiche détachée d'un cadre de l'ouvrage (contenu partiellement hors programme)
A14: M013 | B14: Noir – conforme | C14: BCPST1 | D14: BCPST1 · Outils 3 – Trigonométrie | E14: Formulaire | F14: Formules d'addition | G14: $\cos(a\pm b)=\cos a\cos b\mp\sin a\sin b$ ; $\sin(a\pm b)=\sin a\cos b\pm\cos a\sin b$. | H14: « cos(α ± β) = cos α cos β ∓ sin α sin β ; sin(α ± β) = sin α cos β ± cos α sin β ». (tan(a ± b) : fiche séparée) | I14: 102 | J14: tan(a ± b) placée dans une fiche séparée
A15: M014 | B15: Rouge – hors programme | C15: BCPST1 | D15: BCPST1 · Outils 3 – Trigonométrie | E15: Formulaire | F15: Formule d'addition de la tangente | G15: $\tan(a\pm b)=\dfrac{\tan a\pm\tan b}{1\mp\tan a\tan b}$. | H15: « Les autres formules de trigonométrie ne sont pas des attendus du programme. » | I15: 102 | J15: Fiche détachée d'un cadre de l'ouvrage (contenu partiellement hors programme)
A16: M015 | B16: Noir – conforme | C16: BCPST1 | D16: BCPST1 · Outils 3 – Trigonométrie | E16: Formulaire | F16: Formules de duplication | G16: $\cos2a=\cos^2a-\sin^2a=2\cos^2a-1=1-2\sin^2a$ ; $\sin2a=2\sin a\cos a$. | H16: « cos(2θ) = cos² θ − sin² θ = 2cos² θ − 1 = 1 − 2sin² θ ; sin(2θ) = 2 sin θ cos θ ». (tan 2a : fiche séparée) | I16: 102 | J16: tan 2a placée dans une fiche séparée
A17: M016 | B17: Rouge – hors programme | C17: BCPST1 | D17: BCPST1 · Outils 3 – Trigonométrie | E17: Formulaire | F17: Duplication de la tangente | G17: $\tan2a=\dfrac{2\tan a}{1-\tan^2a}$. | H17: « Les autres formules de trigonométrie ne sont pas des attendus du programme. » | I17: 102 | J17: Fiche détachée d'un cadre de l'ouvrage (contenu partiellement hors programme)
A18: M017 | B18: Rouge – hors programme | C18: BCPST1 | D18: BCPST1 · Outils 3 – Trigonométrie | E18: Formulaire | F18: Expression de cos a, sin a, tan a en fonction de tan(a/2) | G18: Avec $t=\tan\frac a2$ : $\cos a=\frac{1-t^2}{1+t^2}$, $\sin a=\frac{2t}{1+t^2}$, $\tan a=\frac{2t}{1-t^2}$. | H18: « Les autres formules de trigonométrie ne sont pas des attendus du programme. » | I18: 103
A19: M018 | B19: Rouge – hors programme | C19: BCPST1 | D19: BCPST1 · Outils 3 – Trigonométrie | E19: Formulaire | F19: Transformation de produits en sommes (linéarisation) | G19: $\cos a\cos b=\frac12[\cos(a-b)+\cos(a+b)]$ ; $\sin a\sin b=\frac12[\cos(a-b)-\cos(a+b)]$ ; $\sin a\cos b=\frac12[\sin(a+b)+\sin(a-b)]$ ; $\cos^2a=\frac{1+\cos2a}2$ ; $\sin^2a=\frac{1-\cos2a}2$. | H19: « Les autres formules de trigonométrie ne sont pas des attendus du programme. » La linéarisation de cos^p sin^q se fait par les formules d'Euler, « l'énoncé devra l'indiquer ». NB : cos² a = (1 + cos 2a)/2 se déduit directement de la formule de duplication, qui est au programme. | I19: 103
A20: M019 | B20: Rouge – hors programme | C20: BCPST1 | D20: BCPST1 · Outils 3 – Trigonométrie | E20: Formulaire | F20: Transformation de sommes en produits | G20: $\cos p+\cos q=2\cos\frac{p+q}2\cos\frac{p-q}2$ ; $\cos p-\cos q=-2\sin\frac{p+q}2\sin\frac{p-q}2$ ; $\sin p+\sin q=2\sin\frac{p+q}2\cos\frac{p-q}2$ ; $\sin p-\sin q=2\sin\frac{p-q}2\cos\frac{p+q}2$. | H20: « Les autres formules de trigonométrie ne sont pas des attendus du programme. » | I20: 103
A21: M020 | B21: Noir – conforme | C21: BCPST1 | D21: BCPST1 · Outils 3 – Trigonométrie | E21: Formulaire | F21: Arcs associés | G21: $\cos(-a)=\cos a$, $\sin(-a)=-\sin a$ ; $\cos(\pi\pm a)=-\cos a$ ; $\sin(\pi-a)=\sin a$, $\sin(\pi+a)=-\sin a$ ; $\cos(\frac\pi2-a)=\sin a$, $\sin(\frac\pi2-a)=\cos a$ ; $\cos(\frac\pi2+a)=-\sin a$, $\sin(\frac\pi2+a)=\cos a$ ; $\tan(\pi+a)=\tan a$, $\tan(-a)=-\tan a$. | H21: « Formules découlant des symétries de cos, sin et tan. » (les formules en cot de l'ouvrage ont été retirées) | I21: 104 | J21: Formules en cot de l'ouvrage retirées (« autres formules … pas des attendus »)
A22: M021 | B22: Noir – conforme | C22: BCPST1 | D22: BCPST1 · Outils 4 – Nombres complexes | E22: Définition | F22: Forme cartésienne / Forme polaire d'un nombre complexe | G22: $z=a+ib$ avec $a=\mathrm{Re}(z)$, $b=\mathrm{Im}(z)$ ; si $z\neq0$, $z=\rho e^{i\theta}$ avec $\rho=|z|>0$ et $\theta$ un argument de $z$. | H22: « Écriture algébrique … Écriture exponentielle d'un nombre complexe non nul. » | I22: 19
A23: M022 | B23: Noir – conforme | C23: BCPST1 | D23: BCPST1 · Outils 4 – Nombres complexes | E23: Définition | F23: Nombre complexe conjugué – Définition | G23: Si $z=a+ib$, $\bar z=a-ib$. | H23: « Conjugué d'un nombre complexe. » | I23: 19
A24: M023 | B24: Noir – conforme | C24: BCPST1 | D24: BCPST1 · Outils 4 – Nombres complexes | E24: Propriété | F24: Nombre complexe conjugué – Propriétés | G24: $z+\bar z=2\mathrm{Re}(z)$ ; $z-\bar z=2i\,\mathrm{Im}(z)$ ; $z$ réel $\iff\bar z=z$ ; $z$ imaginaire pur $\iff\bar z=-z$. | H24: « Propriétés de la conjugaison … (par exemple pour montrer qu'un nombre complexe est réel ou imaginaire pur). » | I24: 19
A25: M024 | B25: Noir – conforme | C25: BCPST1 | D25: BCPST1 · Outils 4 – Nombres complexes | E25: Propriété | F25: Module d'un nombre complexe | G25: $|z|^2=z\bar z$. | H25: « Module … |z| = √(z z̄) ou |a+ib| = √(a²+b²). » | I25: 19
A26: M025 | B26: Noir – conforme | C26: BCPST1 | D26: BCPST1 · Outils 4 – Nombres complexes | E26: Propriété | F26: Module d'un produit – Module d'un quotient | G26: $|zz'|=|z||z'|$ ; si $z'\neq0$, $\left|\dfrac{z}{z'}\right|=\dfrac{|z|}{|z'|}$. | H26: « Propriétés du module : multiplicativité … » | I26: 19
A27: M026 | B27: Noir – conforme | C27: BCPST1 | D27: BCPST1 · Outils 4 – Nombres complexes | E27: Propriété | F27: Inégalité triangulaire | G27: $|z+z'|\le|z|+|z'|$. | H27: « Propriétés du module : … inégalité triangulaire. » | I27: 20
A28: M027 | B28: Orange – incertain | C28: BCPST1 | D28: BCPST1 · Outils 4 – Nombres complexes | E28: Propriété | F28: Identité remarquable pour le module | G28: $|z+z'|^2=|z|^2+|z'|^2+2\,\mathrm{Re}(z\bar{z'})$. | H28: Programme muet : notion non mentionnée. | I28: 20
A29: M028 | B29: Noir – conforme | C29: BCPST1 | D29: BCPST1 · Outils 4 – Nombres complexes | E29: Définition | F29: Exponentielle d'un imaginaire pur – Définition | G29: Pour $\theta\in\mathbb R$ : $e^{i\theta}=\cos\theta+i\sin\theta$. | H29: « Notation e^{iθ}. Propriétés … formules d'Euler. » | I29: 20
A30: M029 | B30: Noir – conforme | C30: BCPST1 | D30: BCPST1 · Outils 4 – Nombres complexes | E30: Propriété | F30: Exponentielle d'un imaginaire pur – Propriété | G30: $e^{i\theta}=e^{i\theta'}\iff\theta\equiv\theta'\ [2\pi]$ ; $e^{i\theta}=1\iff\theta\equiv0\ [2\pi]$. | H30: « Arguments d'un nombre complexe non nul. » | I30: 20
A31: M030 | B31: Orange – incertain | C31: BCPST1 | D31: BCPST1 · Outils 4 – Nombres complexes | E31: Définition | F31: Exponentielle d'un nombre complexe – Définition | G31: Pour $z\in\mathbb C$ : $e^z=e^{\mathrm{Re}(z)}e^{i\,\mathrm{Im}(z)}$. | H31: Seul e^{iθ} est au programme (et t ↦ e^{αt}, α ∈ C, en Analyse 4) ; l'exponentielle d'un complexe quelconque n'est pas définie comme telle. | I31: 20
A32: M031 | B32: Orange – incertain | C32: BCPST1 | D32: BCPST1 · Outils 4 – Nombres complexes | E32: Propriété | F32: Exponentielle d'un nombre complexe – Propriété | G32: $|e^z|=e^{\mathrm{Re}z}$ ; $\arg(e^z)\equiv\mathrm{Im}z\ [2\pi]$ ; $e^{z+z'}=e^ze^{z'}$ ; $e^z=e^{z'}\iff z\equiv z'\ [2i\pi]$. | H32: Seul e^{iθ} est au programme ; propriétés de e^z non mentionnées. | I32: 20
A33: M032 | B33: Noir – conforme | C33: BCPST1 | D33: BCPST1 · Outils 4 – Nombres complexes | E33: Théorème | F33: Résolution des équations du second degré à coefficients réels | G33: $az^2+bz+c=0$ ($a\neq0$), $\Delta=b^2-4ac$. Si $\Delta>0$ : $z=\frac{-b\pm\sqrt\Delta}{2a}$ ; si $\Delta=0$ : $z=-\frac{b}{2a}$ (racine double) ; si $\Delta<0$ : $z=\frac{-b\pm i\sqrt{-\Delta}}{2a}$ (complexes conjuguées). | H33: « Résolution des équations du second degré à coefficients réels. » | I33: 20 | J33: Coquille dans l'ouvrage : « $\Delta>0$ » écrit deux fois au lieu de $\Delta<0$ pour le 3e cas
A34: M033 | B34: Noir – conforme | C34: BCPST1 | D34: BCPST1 · Outils 4 – Nombres complexes | E34: Propriété | F34: Caractérisation des solutions de az²+bz+c=0 | G34: $z_1,z_2$ sont les solutions ssi $z_1+z_2=-\frac ba$ et $z_1z_2=\frac ca$. | H34: « … somme et produit des solutions. » | I34: 21
A35: M034 | B35: Noir – conforme | C35: BCPST1 | D35: BCPST1 · Outils 4 – Nombres complexes | E35: Théorème | F35: Formule de Moivre | G35: $(\cos\theta+i\sin\theta)^n=\cos n\theta+i\sin n\theta$, i.e. $(e^{i\theta})^n=e^{in\theta}$ ($n\in\mathbb Z$). | H35: « (e^{iθ})ⁿ = e^{inθ} » | I35: 21 | J35: Coquille dans l'ouvrage (« $-$ » au lieu de « $=$ »)
A36: M035 | B36: Noir – conforme | C36: BCPST1 | D36: BCPST1 · Outils 4 – Nombres complexes | E36: Théorème | F36: Formules d'Euler | G36: $\cos x=\dfrac{e^{ix}+e^{-ix}}2$ ; $\sin x=\dfrac{e^{ix}-e^{-ix}}{2i}$. | H36: « formules d'Euler » | I36: 21
A37: M036 | B37: Rouge – hors programme | C37: BCPST1 | D37: BCPST1 · Outils 4 – Nombres complexes | E37: Propriété | F37: Racines n-ièmes d'un complexe | G37: Les solutions de $z^n=re^{i\varphi}$ ($r>0$) sont $z_k=\sqrt[n]r\,e^{i\frac{\varphi+2k\pi}n}$, $0\le k\le n-1$. Racines $n$-ièmes de l'unité : $e^{2ik\pi/n}$. | H37: « La recherche des racines n-ièmes de l'unité ou d'un nombre complexe quelconque dans le cas n ≥ 3 n'est pas non plus un attendu du programme. » | I37: 21
A38: M037 | B38: Noir – conforme | C38: BCPST1 | D38: BCPST1 · Outils 5 – Méthodes de calcul | E38: Définition | F38: Factorielle – Définition | G38: $n!=\prod_{k=1}^{n}k$, avec la convention $0!=1$. | H38: « Factorielle, notation n! » | I38: 1
A39: M038 | B39: Noir – conforme | C39: BCPST1 | D39: BCPST1 · Outils 5 – Méthodes de calcul | E39: Définition | F39: Combinaisons | G39: Pour $p\le n$ : $\binom{n}{p}=\dfrac{n!}{p!(n-p)!}$ = nombre de parties à $p$ éléments d'un ensemble à $n$ éléments. Convention : $\binom{n}{p}=0$ si $p\notin[\![0,n]\!]$. | H39: « Coefficients binomiaux » (définition avec convention 0 si k<0 ou k>n) ; O7 : « Il y a (n p) p-combinaisons de E ». | I39: 2
A40: M039 | B40: Noir – conforme | C40: BCPST1 | D40: BCPST1 · Outils 5 – Méthodes de calcul | E40: Propriété | F40: Combinaisons – Propriétés | G40: Symétrie : $\binom{n}{p}=\binom{n}{n-p}$. Formule de Pascal : $\binom{n}{p}+\binom{n}{p+1}=\binom{n+1}{p+1}$. | H40: « Triangle de Pascal. On met en valeur les formules (n k)=(n n−k) … (n k−1)+(n k)=(n+1 k) ». | I40: 2
...

Sheet Formulaire
A1: ID | B1: Statut | C1: Rubrique | D1: Recto | E1: Verso | F1: Justification (programme 2021) | G1: Fiche d'origine | H1: Page ouvrage | I1: Remarque | J1: Ta décision | K1: Ton commentaire
A2: F001 | B2: Noir – conforme | C2: Trigonométrie | D2: $\cos\left(\frac\pi6\right)$ | E2: $\frac{\sqrt3}2$ | F2: Outils 3 : « Définition de cos(θ), sin(θ) et tan(θ). » Les valeurs remarquables ne sont pas citées, mais sont un prérequis du lycée. | G2: M010 | H2: 102
A3: F002 | B3: Noir – conforme | C3: Trigonométrie | D3: $\cos\left(\frac\pi4\right)$ | E3: $\frac{\sqrt2}2$ | F3: Outils 3 : « Définition de cos(θ), sin(θ) et tan(θ). » Les valeurs remarquables ne sont pas citées, mais sont un prérequis du lycée. | G3: M010 | H3: 102
A4: F003 | B4: Noir – conforme | C4: Trigonométrie | D4: $\cos\left(\frac\pi3\right)$ | E4: $\frac12$ | F4: Outils 3 : « Définition de cos(θ), sin(θ) et tan(θ). » Les valeurs remarquables ne sont pas citées, mais sont un prérequis du lycée. | G4: M010 | H4: 102
A5: F004 | B5: Noir – conforme | C5: Trigonométrie | D5: $\sin\left(\frac\pi6\right)$ | E5: $\frac12$ | F5: Outils 3 : « Définition de cos(θ), sin(θ) et tan(θ). » Les valeurs remarquables ne sont pas citées, mais sont un prérequis du lycée. | G5: M010 | H5: 102
A6: F005 | B6: Noir – conforme | C6: Trigonométrie | D6: $\sin\left(\frac\pi4\right)$ | E6: $\frac{\sqrt2}2$ | F6: Outils 3 : « Définition de cos(θ), sin(θ) et tan(θ). » Les valeurs remarquables ne sont pas citées, mais sont un prérequis du lycée. | G6: M010 | H6: 102
A7: F006 | B7: Noir – conforme | C7: Trigonométrie | D7: $\sin\left(\frac\pi3\right)$ | E7: $\frac{\sqrt3}2$ | F7: Outils 3 : « Définition de cos(θ), sin(θ) et tan(θ). » Les valeurs remarquables ne sont pas citées, mais sont un prérequis du lycée. | G7: M010 | H7: 102
A8: F007 | B8: Noir – conforme | C8: Trigonométrie | D8: $\tan\left(\frac\pi6\right)$ | E8: $\frac{\sqrt3}3=\frac1{\sqrt3}$ | F8: Outils 3 : « Définition de cos(θ), sin(θ) et tan(θ). » Les valeurs remarquables ne sont pas citées, mais sont un prérequis du lycée. | G8: M010 | H8: 102
A9: F008 | B9: Noir – conforme | C9: Trigonométrie | D9: $\tan\left(\frac\pi4\right)$ | E9: $1$ | F9: Outils 3 : « Définition de cos(θ), sin(θ) et tan(θ). » Les valeurs remarquables ne sont pas citées, mais sont un prérequis du lycée. | G9: M010 | H9: 102
A10: F009 | B10: Noir – conforme | C10: Trigonométrie | D10: $\tan\left(\frac\pi3\right)$ | E10: $\sqrt3$ | F10: Outils 3 : « Définition de cos(θ), sin(θ) et tan(θ). » Les valeurs remarquables ne sont pas citées, mais sont un prérequis du lycée. | G10: M010 | H10: 102
A11: F010 | B11: Noir – conforme | C11: Trigonométrie | D11: $\cos^2a+\sin^2a$ | E11: $1$ | F11: Outils 3 : formule citée explicitement dans « Formules de trigonométrie ». | G11: M011 | H11: 102
A12: F011 | B12: Noir – conforme | C12: Trigonométrie | D12: $\tan a$ | E12: $\dfrac{\sin a}{\cos a}$ (pour $\cos a\neq0$) | F12: Outils 3 : « Définition de cos(θ), sin(θ) et tan(θ). » | G12: M011 | H12: 102
A13: F012 | B13: Orange – incertain | C13: Trigonométrie | D13: $1+\tan^2a$ | E13: $\dfrac1{\cos^2a}$ | F13: Outils 3 : « Les autres formules de trigonométrie ne sont pas des attendus du programme. » Formule non citée, mais liée à la définition de tan ou à sa dérivée (Analyse 7). | G13: M011 | H13: 102
... A33: F032 | B33: Noir – conforme | C33: Primitives usuelles | D33: Primitive de $t\mapsto \dfrac1t$ | E33: $\ln|t|$ (sur un intervalle ne contenant pas $0$) | F33: Analyse 3 : « Primitives de u′eᵘ, u′uⁿ, u′/u, u′/√u, u′ sin u, u′ cos u. » | G33: M068 | H33: 98
A34: F033 | B34: Noir – conforme | C34: Primitives usuelles | D34: Primitive de $t\mapsto e^{mt}$ ($m\neq0$) | E34: $\dfrac1m\,e^{mt}$ | F34: Analyse 3 : « Primitives de u′eᵘ, u′uⁿ, u′/u, u′/√u, u′ sin u, u′ cos u. » | G34: M068 | H34: 98 | I34: L'ouvrage prend m complexe non nul ; le programme ne parle que de u′eᵘ.
A35: F034 | B35: Orange – incertain | C35: Primitives usuelles | D35: Primitive de $t\mapsto a^t$ ($a>0$, $a\neq1$) | E35: $\dfrac{a^t}{\ln a}$ | F35: Analyse 3 : primitive non citée dans la liste du programme (u′eᵘ, u′uⁿ, u′/u, u′/√u, u′ sin u, u′ cos u). Se déduit de aᵗ = e^{t ln a}. | G35: M068 | H35: 98
A36: F035 | B36: Noir – conforme | C36: Primitives usuelles | D36: Primitive de $t\mapsto \ln t$ | E36: $t\ln t-t$ | F36: Analyse 3 : « On remarquera que x ↦ x ln(x) − x est une primitive de ln. » | I36: Carte ajoutée : absente de l'ouvrage, citée par le programme.
A37: F036 | B37: Noir – conforme | C37: Primitives usuelles | D37: Primitive de $t\mapsto \cos t$ | E37: $\sin t$ | F37: Analyse 3 : « Primitives de u′eᵘ, u′uⁿ, u′/u, u′/√u, u′ sin u, u′ cos u. » | G37: M069 | H37: 98
A38: F037 | B38: Noir – conforme | C38: Primitives usuelles | D38: Primitive de $t\mapsto \sin t$ | E38: $-\cos t$ | F38: Analyse 3 : « Primitives de u′eᵘ, u′uⁿ, u′/u, u′/√u, u′ sin u, u′ cos u. » | G38: M069 | H38: 98
A39: F038 | B39: Orange – incertain | C39: Primitives usuelles | D39: Primitive de $t\mapsto \dfrac1{\cos^2t}$ | E39: $\tan t$ | F39: Analyse 3 : primitive non citée dans la liste du programme (u′eᵘ, u′uⁿ, u′/u, u′/√u, u′ sin u, u′ cos u). Se déduit de la dérivée de tan. | G39: M069 | H39: 98
A40: F039 | B40: Orange – incertain | C40: Primitives usuelles | D40: Primitive de $t\mapsto \tan t$ | E40: $-\ln|\cos t|$ | F40: Analyse 3 : primitive non citée dans la liste du programme (u′eᵘ, u′uⁿ, u′/u, u′/√u, u′ sin u, u′ cos u). Cas particulier de u′/u (u = cos). | G40: M069 | H40: 98
A41: F040 | B41: Orange – incertain | C41: Primitives usuelles | D41: Primitive de $t\mapsto \dfrac1{\cos t}$ | E41: $\ln\left|\tan\left(\dfrac t2+\dfrac\pi4\right)\right|$ | F41: Analyse 3 : primitive non citée dans la liste du programme (u′eᵘ, u′uⁿ, u′/u, u′/√u, u′ sin u, u′ cos u). | G41: M070 | H41: 98
A42: F041 | B42: Orange – incertain | C42: Primitives usuelles | D42: Primitive de $t\mapsto \dfrac1{\sin t}$ | E42: $\ln\left|\tan\dfrac t2\right|$ | F42: Analyse 3 : primitive non citée dans la liste du programme (u′eᵘ, u′uⁿ, u′/u, u′/√u, u′ sin u, u′ cos u). | G42: M070 | H42: 98
A43: F042 | B43: Orange – incertain | C43: Primitives usuelles | D43: Primitive de $t\mapsto \dfrac1{\sin^2t}$ | E43: $-\dfrac{\cos t}{\sin t}$ | F43: Analyse 3 : primitive non citée dans la liste du programme (u′eᵘ, u′uⁿ, u′/u, u′/√u, u′ sin u, u′ cos u). | G43: M070 | H43: 98 | I43: L'ouvrage écrit −cot t ; la cotangente n'est pas au programme, d'où l'écriture cos/sin.
A44: F043 | B44: Orange – incertain | C44: Primitives usuelles | D44: Primitive de $t\mapsto \dfrac{\cos t}{\sin t}$ | E44: $\ln|\sin t|$ | F44: Analyse 3 : primitive non citée dans la liste du programme (u′eᵘ, u′uⁿ, u′/u, u′/√u, u′ sin u, u′ cos u). Cas particulier de u′/u (u = sin). | G44: M070 | H44: 98 | I44: L'ouvrage écrit cot t ; la cotangente n'est pas au programme.
A45: F044 | B45: Noir – conforme | C45: Primitives usuelles | D45: Primitive de $t\mapsto \dfrac1{t^2+a^2}$ ($a\neq0$) | E45: $\dfrac1a\arctan\dfrac ta$ | F45: Analyse 7 : « Dérivée de la fonction arctan. » La primitive de 1/(1+t²) en découle directement. | G45: M228 | H45: 99
A46: F045 | B46: Orange – incertain | C46: Primitives usuelles | D46: Primitive de $t\mapsto \dfrac1{\sqrt{a^2-t^2}}$ sur $]-|a|,|a|[$ | E46: $\arcsin\dfrac t{|a|}$ | F46: Analyse 3 : primitive non citée dans la liste du programme (u′eᵘ, u′uⁿ, u′/u, u′/√u, u′ sin u, u′ cos u). La construction d'arcsin n'est pas un attendu (Outils 3). | G46: M071 | H46: 99
A47: F046 | B47: Orange – incertain | C47: Primitives usuelles | D47: Primitive de $t\mapsto \dfrac1{\sqrt{t^2+b}}$ | E47: $\ln\left|t+\sqrt{t^2+b}\right|$ | F47: Analyse 3 : primitive non citée dans la liste du programme (u′eᵘ, u′uⁿ, u′/u, u′/√u, u′ sin u, u′ cos u). | G47: M071 | H47: 99
A48: F047 | B48: Orange – incertain | C48: Primitives usuelles | D48: Primitive de $t\mapsto \dfrac1{t^2-a^2}$ ($a\neq0$) | E48: $\dfrac1{2a}\ln\left|\dfrac{t-a}{t+a}\right|$ | F48: Analyse 3 : primitive non citée dans la liste du programme (u′eᵘ, u′uⁿ, u′/u, u′/√u, u′ sin u, u′ cos u). Se retrouve par décomposition en éléments simples. | G48: M071 | H48: 99
A49: F048 | B49: Noir – conforme | C49: Développements limités usuels en 0 | D49: DL de $e^x$ en $0$ à l'ordre $n$ | E49: $\displaystyle\sum_{k=0}^n\frac{x^k}{k!}+o(x^n)=1+x+\frac{x^2}{2}+\dots+\frac{x^n}{n!}+o(x^n)$ | F49: Analyse 9 : « Développements limités usuels au voisinage de 0 : exp, cos, sin, x ↦ 1/(1+x), x ↦ ln(1+x), x ↦ (1+x)^α. » | G49: M258 | H49: 100
A50: F049 | B50: Noir – conforme | C50: Développements limités usuels en 0 | D50: DL de $\cos x$ en $0$ à l'ordre $2n+1$ | E50: $\displaystyle\sum_{k=0}^n(-1)^k\frac{x^{2k}}{(2k)!}+o(x^{2n+1})=1-\frac{x^2}2+\frac{x^4}{24}-\dots$ | F50: Analyse 9 : « Développements limités usuels au voisinage de 0 : exp, cos, sin, x ↦ 1/(1+x), x ↦ ln(1+x), x ↦ (1+x)^α. » | G50: M259 | H50: 100
A51: F050 | B51: Noir – conforme | C51: Développements limités usuels en 0 | D51: DL de $\sin x$ en $0$ à l'ordre $2n+2$ | E51: $\displaystyle\sum_{k=0}^n(-1)^k\frac{x^{2k+1}}{(2k+1)!}+o(x^{2n+2})=x-\frac{x^3}6+\dots$ | F51: Analyse 9 : « Développements limités usuels au voisinage de 0 : exp, cos, sin, x ↦ 1/(1+x), x ↦ ln(1+x), x ↦ (1+x)^α. » | G51: M259 | H51: 100
A52: F051 | B52: Noir – conforme | C52: Développements limités usuels en 0 | D52: DL de $\dfrac1{1+x}$ en $0$ à l'ordre $n$ | E52: $\displaystyle\sum_{k=0}^n(-1)^kx^k+o(x^n)=1-x+x^2-\dots+(-1)^nx^n+o(x^n)$ | F52: Analyse 9 : « Développements limités usuels au voisinage de 0 : exp, cos, sin, x ↦ 1/(1+x), x ↦ ln(1+x), x ↦ (1+x)^α. » | I52: Carte ajoutée : l'ouvrage donne 1/(1−x), le programme cite 1/(1+x).
A53: F052 | B53: Noir – conforme | C53: Développements limités usuels en 0 | D53: DL de $\dfrac1{1-x}$ en $0$ à l'ordre $n$ | E53: $\displaystyle\sum_{k=0}^nx^k+o(x^n)=1+x+x^2+\dots+x^n+o(x^n)$ | F53: Analyse 9 : « Développements limités usuels au voisinage de 0 : exp, cos, sin, x ↦ 1/(1+x), x ↦ ln(1+x), x ↦ (1+x)^α. » (1/(1−x) s'en déduit en changeant x en −x.) | G53: M257 | H53: 100
A54: F053 | B54: Noir – conforme | C54: Développements limités usuels en 0 | D54: DL de $\ln(1+x)$ en $0$ à l'ordre $n$ | E54: $\displaystyle\sum_{k=1}^n(-1)^{k+1}\frac{x^k}k+o(x^n)=x-\frac{x^2}2+\frac{x^3}3-\dots$ | F54: Analyse 9 : « Développements limités usuels au voisinage de 0 : exp, cos, sin, x ↦ 1/(1+x), x ↦ ln(1+x), x ↦ (1+x)^α. » | G54: M258 | H54: 100
A55: F054 | B55: Orange – incertain | C55: Développements limités usuels en 0 | D55: DL de $\ln(1-x)$ en $0$ à l'ordre $n$ | E55: $\displaystyle-\sum_{k=1}^n\frac{x^k}k+o(x^n)=-x-\frac{x^2}2-\frac{x^3}3-\dots$ | F55: Analyse 9 : DL non cité dans la liste des DL usuels (exp, cos, sin, 1/(1+x), ln(1+x), (1+x)^α) ; il s'en déduit. | G55: M258 | H55: 100
A56: F055 | B56: Noir – conforme | C56: Développements limités usuels en 0 | D56: DL de $(1+x)^\alpha$ en $0$ à l'ordre $n$ | E56: $1+\alpha x+\dfrac{\alpha(\alpha-1)}{2!}x^2+\dots+\dfrac{\alpha(\alpha-1)\cdots(\alpha-n+1)}{n!}x^n+o(x^n)$ | F56: Analyse 9 : « Développements limités usuels au voisinage de 0 : exp, cos, sin, x ↦ 1/(1+x), x ↦ ln(1+x), x ↦ (1+x)^α. » | G56: M257 | H56: 100
A57: F056 | B57: Orange – incertain | C57: Développements limités usuels en 0 | D57: DL de $\sqrt{1+x}$ en $0$ à l'ordre $2$ | E57: $1+\dfrac x2-\dfrac{x^2}8+o(x^2)$ | F57: Analyse 9 : DL non cité dans la liste des DL usuels (exp, cos, sin, 1/(1+x), ln(1+x), (1+x)^α) ; il s'en déduit. Cas α = 1/2. | G57: M257 | H57: 100
A58: F057 | B58: Orange – incertain | C58: Développements limités usuels en 0 | D58: DL de $\dfrac1{\sqrt{1+x}}$ en $0$ à l'ordre $2$ | E58: $1-\dfrac x2+\dfrac38x^2+o(x^2)$ | F58: Analyse 9 : DL non cité dans la liste des DL usuels (exp, cos, sin, 1/(1+x), ln(1+x), (1+x)^α) ; il s'en déduit. Cas α = −1/2. | G58: M257 | H58: 100
A59: F058 | B59: Orange – incertain | C59: Développements limités usuels en 0 | D59: DL de $\tan x$ en $0$ à l'ordre $3$ | E59: $x+\dfrac{x^3}3+o(x^3)$ | F59: Analyse 9 : DL non cité dans la liste des DL usuels (exp, cos, sin, 1/(1+x), ln(1+x), (1+x)^α) ; il s'en déduit. | G59: M260 | H59: 100
...

Sheet Synthèse
A1: Répartition des fiches
A3: Statut | B3: Nombre de fiches | C3: Part
A4: Noir – conforme | B4: =COUNTIF(Fiches!$B$2:$B$461,A4) | C4: =IF($B$7=0,0,B4/$B$7)
A5: Orange – incertain | B5: =COUNTIF(Fiches!$B$2:$B$461,A5) | C5: =IF($B$7=0,0,B5/$B$7)
A6: Rouge – hors programme | B6: =COUNTIF(Fiches!$B$2:$B$461,A6) | C6: =IF($B$7=0,0,B6/$B$7)
A7: Total | B7: =SUM(B4:B6)
A9: Décisions saisies | B9: =COUNTA(Fiches!$K$2:$K$461)
A11: Par partie du programme
A12: Partie | B12: Noir | C12: Orange | D12: Rouge | E12: Total
A13: BCPST1 · Outils 1 – Logique, ensembles | B13: =COUNTIFS(Fiches!$D$2:$D$461,$A13,Fiches!$B$2:$B$461,"Noir – conforme") | C13: =COUNTIFS(Fiches!$D$2:$D$461,$A13,Fiches!$B$2:$B$461,"Orange – incertain") | D13: =COUNTIFS(Fiches!$D$2:$D$461,$A13,Fiches!$B$2:$B$461,"Rouge – hors programme") | E13: =SUM(B13:D13)
A14: BCPST1 · Outils 2 – Nombres réels | B14: =COUNTIFS(Fiches!$D$2:$D$461,$A14,Fiches!$B$2:$B$461,"Noir – conforme") | C14: =COUNTIFS(Fiches!$D$2:$D$461,$A14,Fiches!$B$2:$B$461,"Orange – incertain") | D14: =COUNTIFS(Fiches!$D$2:$D$461,$A14,Fiches!$B$2:$B$461,"Rouge – hors programme") | E14: =SUM(B14:D14)
A15: BCPST1 · Outils 3 – Trigonométrie | B15: =COUNTIFS(Fiches!$D$2:$D$461,$A15,Fiches!$B$2:$B$461,"Noir – conforme") | C15: =COUNTIFS(Fiches!$D$2:$D$461,$A15,Fiches!$B$2:$B$461,"Orange – incertain") | D15: =COUNTIFS(Fiches!$D$2:$D$461,$A15,Fiches!$B$2:$B$461,"Rouge – hors programme") | E15: =SUM(B15:D15)
A16: BCPST1 · Outils 4 – Nombres complexes | B16: =COUNTIFS(Fiches!$D$2:$D$461,$A16,Fiches!$B$2:$B$461,"Noir – conforme") | C16: =COUNTIFS(Fiches!$D$2:$D$461,$A16,Fiches!$B$2:$B$461,"Orange – incertain") | D16: =COUNTIFS(Fiches!$D$2:$D$461,$A16,Fiches!$B$2:$B$461,"Rouge – hors programme") | E16: =SUM(B16:D16)
A17: BCPST1 · Outils 5 – Méthodes de calcul | B17: =COUNTIFS(Fiches!$D$2:$D$461,$A17,Fiches!$B$2:$B$461,"Noir – conforme") | C17: =COUNTIFS(Fiches!$D$2:$D$461,$A17,Fiches!$B$2:$B$461,"Orange – incertain") | D17: =COUNTIFS(Fiches!$D$2:$D$461,$A17,Fiches!$B$2:$B$461,"Rouge – hors programme") | E17: =SUM(B17:D17)
A18: BCPST1 · Outils 6 – Vocabulaire des applications | B18: =COUNTIFS(Fiches!$D$2:$D$461,$A18,Fiches!$B$2:$B$461,"Noir – conforme") | C18: =COUNTIFS(Fiches!$D$2:$D$461,$A18,Fiches!$B$2:$B$461,"Orange – incertain") | D18: =COUNTIFS(Fiches!$D$2:$D$461,$A18,Fiches!$B$2:$B$461,"Rouge – hors programme") | E18: =SUM(B18:D18)
A19: BCPST1 · Outils 7 – Dénombrement | B19: =COUNTIFS(Fiches!$D$2:$D$461,$A19,Fiches!$B$2:$B$461,"Noir – conforme") | C19: =COUNTIFS(Fiches!$D$2:$D$461,$A19,Fiches!$B$2:$B$461,"Orange – incertain") | D19: =COUNTIFS(Fiches!$D$2:$D$461,$A19,Fiches!$B$2:$B$461,"Rouge – hors programme") | E19: =SUM(B19:D19)
A20: BCPST1 · Analyse 1 – Suites réelles usuelles | B20: =COUNTIFS(Fiches!$D$2:$D$461,$A20,Fiches!$B$2:$B$461,"Noir – conforme") | C20: =COUNTIFS(Fiches!$D$2:$D$461,$A20,Fiches!$B$2:$B$461,"Orange – incertain") | D20: =COUNTIFS(Fiches!$D$2:$D$461,$A20,Fiches!$B$2:$B$461,"Rouge – hors programme") | E20: =SUM(B20:D20)
A21: BCPST1 · Analyse 2 – Fonctions réelles usuelles | B21: =COUNTIFS(Fiches!$D$2:$D$461,$A21,Fiches!$B$2:$B$461,"Noir – conforme") | C21: =COUNTIFS(Fiches!$D$2:$D$461,$A21,Fiches!$B$2:$B$461,"Orange – incertain") | D21: =COUNTIFS(Fiches!$D$2:$D$461,$A21,Fiches!$B$2:$B$461,"Rouge – hors programme") | E21: =SUM(B21:D21)
A22: BCPST1 · Analyse 3 – Dérivées, primitives, intégrales | B22: =COUNTIFS(Fiches!$D$2:$D$461,$A22,Fiches!$B$2:$B$461,"Noir – conforme") | C22: =COUNTIFS(Fiches!$D$2:$D$461,$A22,Fiches!$B$2:$B$461,"Orange – incertain") | D22: =COUNTIFS(Fiches!$D$2:$D$461,$A22,Fiches!$B$2:$B$461,"Rouge – hors programme") | E22: =SUM(B22:D22)
A23: BCPST1 · Analyse 4 – Équations différentielles linéaires | B23: =COUNTIFS(Fiches!$D$2:$D$461,$A23,Fiches!$B$2:$B$461,"Noir – conforme") | C23: =COUNTIFS(Fiches!$D$2:$D$461,$A23,Fiches!$B$2:$B$461,"Orange – incertain") | D23: =COUNTIFS(Fiches!$D$2:$D$461,$A23,Fiches!$B$2:$B$461,"Rouge – hors programme") | E23: =SUM(B23:D23)
A24: BCPST1 · Algèbre linéaire 1 – Systèmes linéaires | B24: =COUNTIFS(Fiches!$D$2:$D$461,$A24,Fiches!$B$2:$B$461,"Noir – conforme") | C24: =COUNTIFS(Fiches!$D$2:$D$461,$A24,Fiches!$B$2:$B$461,"Orange – incertain") | D24: =COUNTIFS(Fiches!$D$2:$D$461,$A24,Fiches!$B$2:$B$461,"Rouge – hors programme") | E24: =SUM(B24:D24)
... A48: Hors des chapitres du programme | B48: =COUNTIFS(Fiches!$D$2:$D$461,$A48,Fiches!$B$2:$B$461,"Noir – conforme") | C48: =COUNTIFS(Fiches!$D$2:$D$461,$A48,Fiches!$B$2:$B$461,"Orange – incertain") | D48: =COUNTIFS(Fiches!$D$2:$D$461,$A48,Fiches!$B$2:$B$461,"Rouge – hors programme") | E48: =SUM(B48:D48)

Sheet Erreurs ouvrage
A1: ID fiche | B1: Page | C1: Intitulé | D1: Problème relevé dans l'ouvrage | E1: Gravité
A2: M008 | B2: 21 | C2: Factorisation de a cos θ + b sin θ | D2: ERREUR DANS L'OUVRAGE : il écrit $r\cos(\theta+\varphi)$ avec $\sin\varphi=b/r$ ; avec cette convention il faut $\sin\varphi=-b/r$ (ou bien $r\cos(\theta-\varphi)$). Corrigé ici dans la forme du programme | E2: Erreur mathématique
A3: M032 | B3: 20 | C3: Résolution des équations du second degré à coefficients réels | D3: Coquille dans l'ouvrage : « $\Delta>0$ » écrit deux fois au lieu de $\Delta<0$ pour le 3e cas | E3: Coquille / imprécision
A4: M034 | B4: 21 | C4: Formule de Moivre | D4: Coquille dans l'ouvrage (« $-$ » au lieu de « $=$ ») | E4: Coquille / imprécision
A5: M053 | B5: 74 | C5: Applications et p-uplets | D5: ERREUR DANS L'OUVRAGE : il écrit « sans remise » ; c'est AVEC remise | E5: Erreur mathématique
A6: M054 | B6: 74 | C6: Injections et p-uplets d'éléments distincts | D6: ERREUR DANS L'OUVRAGE : il écrit « avec remise » ; c'est SANS remise | E6: Erreur mathématique
A7: M067 | B7: 104 | C7: Trigonométrie hyperbolique | D7: ERREUR DANS L'OUVRAGE : $\mathrm{th}(a-b)$ a pour numérateur $\mathrm{th}\,a-\mathrm{th}\,b$ (l'ouvrage écrit $+$) | E7: Erreur mathématique
A8: M094 | B8: 14 | C8: Transposée d'une matrice – Règles de calcul | D8: ERREUR PROBABLE DANS L'OUVRAGE : il écrit ${}^t(A+\lambda B)=\lambda{}^tA+{}^tB$ ; corrigé ici | E8: Erreur mathématique
A9: M113 | B9: 56 | C9: Parallélisme de deux droites – Définition | D9: ERREUR DANS L'OUVRAGE : il écrit « tout vecteur directeur de $D_1$ est orthogonal à tout vecteur directeur de $D_2$ » ; corrigé (colinéaire) | E9: Erreur mathématique
A10: M141 | B10: 62 | C10: Bases et repères orthonormaux (espace) | D10: L'ouvrage n'écrit que $\vec i\cdot\vec j=0$ et omet $\|\vec k\|=1$ (cadre incomplet) | E10: Coquille / imprécision
A11: M147 | B11: 66 | C11: Parallélisme de deux plans – Définition | D11: Coquille dans l'ouvrage (« deux droites ») | E11: Coquille / imprécision
A12: M171 | B12: 22 | C12: Suites extraites des rangs pairs et impairs | D12: Coquille dans l'ouvrage (indices mélangés) ; énoncé rétabli | E12: Coquille / imprécision
A13: M193 | B13: 28 | C13: Théorème des gendarmes (fonctions, limites finies) | D13: Coquille dans l'ouvrage (rôles de $g$ et $h$ inversés) ; énoncé rétabli | E13: Coquille / imprécision
... A24: M458 | B24: 71 | C24: Produit vectoriel – Propriété (orthogonalité) | D24: ERREUR DANS L'OUVRAGE : il écrit « non colinéaires et unitaires », il faut « orthogonaux et unitaires » ; corrigé | E24: Erreur mathématique
